Workbook
Name ActiveList: _xlfn.ANCHORARRAY(Assumptions!$B$16)
Name asset_renewal: Assets!$E$21:$E$29
Name asset_sentence: Assets!$B$31
Name assets_table: Assets!$B$6
Name BaseYear: Assumptions!$E$12
Name checks_status: Checks!$G$5:$G$21
Name checks_summary: Checks!$B$2
Name dash_commentary: Dashboard!$B$18:$B$22
Name dash_tiles: Dashboard!$B$6:$M$6,Dashboard!$B$12:$M$12
Name debt_amount: Debt!$F$16
Name debt_capacity: Debt!$F$8
Name debt_capacity_after: Debt!$F$18
Name debt_history: Debt!$B$25:$E$30
Name debt_limit: Debt!$F$6
Name debt_limit_used: Debt!$F$9
Name debt_max_borrowing: Debt!$F$19
Name debt_outstanding: Debt!$F$10
Name debt_payment: Debt!$F$17
Name debt_rate: Debt!$F$14
Name debt_revenue_for_limit: Debt!$F$5
Name debt_sentence: Debt!$B$21
Name debt_servicing: Debt!$F$7
Name debt_term: Debt!$F$15
Name LatestYear: Assumptions!$E$11
Name peer_benchmark: Peers!$B$6:$I$18
Name peer_metric_input: Peers!$D$22
Name peer_ranking: Peers!$B$24
Name plan_avg_increase: Plan!$E$32
Name plan_base_capital: Plan!$J$9
Name plan_base_year: Plan!$J$5
Name plan_closure: Plan!$E$8
Name plan_cost_growth: Plan!$J$7
Name plan_cpi: Plan!$E$5
Name plan_debt: Plan!$E$9
Name plan_gap: Plan!$J$10
Name plan_grid: Plan!$D$37:$H$41
Name plan_pop_growth: Plan!$J$6
Name plan_rate: Plan!$E$11
Name plan_reserve: Plan!$E$10
Name plan_rev_growth: Plan!$J$8
Name plan_sentence: Plan!$B$33
Name plan_table: Plan!$D$16:$I$30
Name plan_term: Plan!$E$12
Name plan_wage: Plan!$E$6
Name plan_wage_share: Plan!$E$7
Name plan_year1_increase: Plan!$E$26
Name profile_block: Profile!$D$6:$I$35
Name profile_keys: Profile!$C$6:$C$35
Name profile_years: Profile!$D$5:$I$5
Name prov_amp_full: Province!$H$19
Name prov_below: Province!$H$16
Name prov_missing: Province!$H$20
Name prov_not_reported: Province!$H$18
Name prov_reinvestment: Province!$H$17
Name prov_screened: Province!$H$15
Name prov_vancouver_rate: Province!$H$21
Name province_sentence: Province!$B$23
Name province_trend: Province!$B$6:$J$11
Name Selected: Dashboard!$C$3
Name SelId: Assumptions!$E$5

Sheet Cover
B2: BC local government finance model
B3: ="Every municipality in British Columbia, 2019-"&LatestYear&": benchmarks, infrastructure renewal, a five-year financial plan, property tax by class and borrowing room. Now showing: "&Selected&"." -> Every municipality in British Columbia, 2019-2024: benchmarks, infrastructure renewal, a five-year financial plan, property tax by class and borrowing room. Now showing: Fernie.
B5: Independent analysis of the Province of British Columbia's Local Government Statistics. Not affiliated with or endorsed by any municipality or by the Province.
B7: How to use it
B8: 1. Pick a municipality in the yellow cell on the Dashboard. Every sheet follows.
B9: 2. Change the plan drivers on Plan: inflation, wages, how much of the renewal gap to close, and how much of it to borrow.
B10: 3. Test a levy change on Tax, and a borrowing amount on Debt.
B11: 4. Rank a municipality's tier on any metric on Peers.
B12: 5. Checks proves the numbers; Province shows how far the asset data can be trusted.
B14: Sheets
B15: Dashboard | C15: Eight tiles against the peer tier, five sentences written by formulas, two charts
B16: Profile | C16: Six years of revenue, expenses, position, debt, assets and tax
B17: Peers | C17: Thirteen metrics with tier and province percentiles; the tier ranked on any of them
B18: Assets | C18: Schedule 503 by category; renewal need and the reinvestment ratio
B19: Plan | C19: A five-year financial plan and a what-if data table over its two big choices
B20: Tax | C20: Assessment, rates and multiples by class; a levy-to-rates calculator
B21: Debt | C21: The legal servicing limit, the room left, and what it would borrow
B22: Province | C22: Totals by year and the asset data-quality screen
B23: Checks | C23: 17 controls, each with a tolerance
B25: Sources
B26: Province of British Columbia, Ministry of Municipal Affairs: Local Government Statistics, schedules 201-707, 2019-2024. Open Government Licence – British Columbia.
B27: Pipeline: pipeline/ (bronze and silver, held to contracts), dbt/ (gold marts and 31 data tests). data/sources.json records every file's URL and SHA-256.

Sheet Dashboard
B1: ="BC local government finance: "&Selected -> BC local government finance: Fernie
B3: Municipality | C3: Fernie | G3: {=SelType&" in the "&SelRD&" regional district · population "&TEXT(YV(tbl_Year[population],LatestYear),"#,##0")&" · peer tier "&SelTierLabel&" ("&SelTierCount&" municipalities) · statements through "&BaseYear} -> City in the EKO regional district · population 6,000 · peer tier 2,500 to 9,999 residents (47 municipalities) · statements through 2024
B5: Own-source share of revenue | E5: Share of the legal debt-servicing limit used | H5: Reserves against a year of cash spending | K5: Share of asset life used up
B6: {=_xlfn.LET(_xlpm.v,_xlfn.XLOOKUP(SelId,tbl_Peers[municipality_id],_xlfn.XLOOKUP("own_source_share",tbl_Peers[#Headers],tbl_Peers[]),""),IF(_xlpm.v="","not reported",_xlpm.v))} -> 0.89259257 | E6: {=_xlfn.LET(_xlpm.v,_xlfn.XLOOKUP(SelId,tbl_Peers[municipality_id],_xlfn.XLOOKUP("limit_used",tbl_Peers[#Headers],tbl_Peers[]),""),IF(_xlpm.v="","not reported",_xlpm.v))} -> 0.15192215 | H6: {=_xlfn.LET(_xlpm.v,_xlfn.XLOOKUP(SelId,tbl_Peers[municipality_id],_xlfn.XLOOKUP("reserves_to_cash_expenses",tbl_Peers[#Headers],tbl_Peers[]),""),IF(_xlpm.v="","not reported",_xlpm.v))} -> 0.75543501 | K6: {=_xlfn.LET(_xlpm.v,_xlfn.XLOOKUP(SelId,tbl_Peers[municipality_id],_xlfn.XLOOKUP("asset_consumption_ratio",tbl_Peers[#Headers],tbl_Peers[]),""),IF(_xlpm.v="","not reported",_xlpm.v))} -> 0.41173021
B7: {="tier median "&TEXT(_xlfn.XLOOKUP(SelId,tbl_Peers[municipality_id],_xlfn.XLOOKUP("own_source_share_tier_median",tbl_Peers[#Headers],tbl_Peers[])),"0.0%")} -> tier median 77.3% | E7: {="tier median "&TEXT(_xlfn.XLOOKUP(SelId,tbl_Peers[municipality_id],_xlfn.XLOOKUP("limit_used_tier_median",tbl_Peers[#Headers],tbl_Peers[])),"0.0%")} -> tier median 15.4% | H7: {="tier median "&TEXT(_xlfn.XLOOKUP(SelId,tbl_Peers[municipality_id],_xlfn.XLOOKUP("reserves_to_cash_expenses_tier_median",tbl_Peers[#Headers],tbl_Peers[])),"0.00""x""")} -> tier median 1.83x | K7: {="tier median "&TEXT(_xlfn.XLOOKUP(SelId,tbl_Peers[municipality_id],_xlfn.XLOOKUP("asset_consumption_ratio_tier_median",tbl_Peers[#Headers],tbl_Peers[])),"0.0%")} -> tier median 42.6%
B8: =_xlfn.XLOOKUP("own_source_share",Peers!$C$6:$C$18,Peers!$I$6:$I$18) -> better than the tier median | E8: =_xlfn.XLOOKUP("limit_used",Peers!$C$6:$C$18,Peers!$I$6:$I$18) -> better than the tier median | H8: =_xlfn.XLOOKUP("reserves_to_cash_expenses",Peers!$C$6:$C$18,Peers!$I$6:$I$18) -> weaker than the tier median | K8: =_xlfn.XLOOKUP("asset_consumption_ratio",Peers!$C$6:$C$18,Peers!$I$6:$I$18) -> better than the tier median
B9: =IFERROR("percentile in tier: "&TEXT(_xlfn.XLOOKUP("own_source_share",Peers!$C$6:$C$18,Peers!$F$6:$F$18),"0%"),"") -> percentile in tier: 98% | E9: =IFERROR("percentile in tier: "&TEXT(_xlfn.XLOOKUP("limit_used",Peers!$C$6:$C$18,Peers!$F$6:$F$18),"0%"),"") -> percentile in tier: 49% | H9: =IFERROR("percentile in tier: "&TEXT(_xlfn.XLOOKUP("reserves_to_cash_expenses",Peers!$C$6:$C$18,Peers!$F$6:$F$18),"0%"),"") -> percentile in tier: 2% | K9: =IFERROR("percentile in tier: "&TEXT(_xlfn.XLOOKUP("asset_consumption_ratio",Peers!$C$6:$C$18,Peers!$F$6:$F$18),"0%"),"") -> percentile in tier: 40%
B11: Capital reinvestment against renewal need | E11: Taxes and charges on a representative house | H11: Municipal property tax per resident | K11: Long-term debt per resident
B12: {=_xlfn.LET(_xlpm.v,_xlfn.XLOOKUP(SelId,tbl_Peers[municipality_id],_xlfn.XLOOKUP("reinvestment_ratio",tbl_Peers[#Headers],tbl_Peers[]),""),IF(_xlpm.v="","not reported",_xlpm.v))} -> 0.95779831 | E12: {=_xlfn.LET(_xlpm.v,_xlfn.XLOOKUP(SelId,tbl_Peers[municipality_id],_xlfn.XLOOKUP("house_total_charges",tbl_Peers[#Headers],tbl_Peers[]),""),IF(_xlpm.v="","not reported",_xlpm.v))} -> 6264 | H12: {=_xlfn.LET(_xlpm.v,_xlfn.XLOOKUP(SelId,tbl_Peers[municipality_id],_xlfn.XLOOKUP("municipal_tax_per_capita",tbl_Peers[#Headers],tbl_Peers[]),""),IF(_xlpm.v="","not reported",_xlpm.v))} -> 2326.3268 | K12: {=_xlfn.LET(_xlpm.v,_xlfn.XLOOKUP(SelId,tbl_Peers[municipality_id],_xlfn.XLOOKUP("debt_per_capita",tbl_Peers[#Headers],tbl_Peers[]),""),IF(_xlpm.v="","not reported",_xlpm.v))} -> 427.6825
B13: {="tier median "&TEXT(_xlfn.XLOOKUP(SelId,tbl_Peers[municipality_id],_xlfn.XLOOKUP("reinvestment_ratio_tier_median",tbl_Peers[#Headers],tbl_Peers[])),"0.00""x""")} -> tier median 1.06x | E13: {="tier median "&TEXT(_xlfn.XLOOKUP(SelId,tbl_Peers[municipality_id],_xlfn.XLOOKUP("house_total_charges_tier_median",tbl_Peers[#Headers],tbl_Peers[])),"$#,##0")} -> tier median $4,507 | H13: {="tier median "&TEXT(_xlfn.XLOOKUP(SelId,tbl_Peers[municipality_id],_xlfn.XLOOKUP("municipal_tax_per_capita_tier_median",tbl_Peers[#Headers],tbl_Peers[])),"$#,##0")} -> tier median $1,246 | K13: {="tier median "&TEXT(_xlfn.XLOOKUP(SelId,tbl_Peers[municipality_id],_xlfn.XLOOKUP("debt_per_capita_tier_median",tbl_Peers[#Headers],tbl_Peers[])),"$#,##0")} -> tier median $950
B14: =_xlfn.XLOOKUP("reinvestment_ratio",Peers!$C$6:$C$18,Peers!$I$6:$I$18) -> weaker than the tier median | E14: =_xlfn.XLOOKUP("house_total_charges",Peers!$C$6:$C$18,Peers!$I$6:$I$18) -> weaker than the tier median | H14: =_xlfn.XLOOKUP("municipal_tax_per_capita",Peers!$C$6:$C$18,Peers!$I$6:$I$18) -> above the tier median | K14: =_xlfn.XLOOKUP("debt_per_capita",Peers!$C$6:$C$18,Peers!$I$6:$I$18) -> better than the tier median
B15: =IFERROR("percentile in tier: "&TEXT(_xlfn.XLOOKUP("reinvestment_ratio",Peers!$C$6:$C$18,Peers!$F$6:$F$18),"0%"),"") -> percentile in tier: 44% | E15: =IFERROR("percentile in tier: "&TEXT(_xlfn.XLOOKUP("house_total_charges",Peers!$C$6:$C$18,Peers!$F$6:$F$18),"0%"),"") -> percentile in tier: 87% | H15: =IFERROR("percentile in tier: "&TEXT(_xlfn.XLOOKUP("municipal_tax_per_capita",Peers!$C$6:$C$18,Peers!$F$6:$F$18),"0%"),"") -> percentile in tier: 96% | K15: =IFERROR("percentile in tier: "&TEXT(_xlfn.XLOOKUP("debt_per_capita",Peers!$C$6:$C$18,Peers!$F$6:$F$18),"0%"),"") -> percentile in tier: 27%
B17: What the numbers say
B18: {=Selected&", "&LatestYear&": revenue "&MONEY(YV(tbl_Year[total_revenue],BaseYear))&", expenses "&MONEY(YV(tbl_Year[total_expenses],BaseYear))&", a surplus of "&MONEY(YV(tbl_Year[annual_surplus],BaseYear))&" ("&TEXT(YV(tbl_Year[surplus_ratio],BaseYear),"0.0%")&" of revenue); "&TEXT(YV(tbl_Year[own_source_share],BaseYear),"0%")&" of revenue is its own."} -> Fernie, 2024: revenue $24.5M, expenses $22.0M, a surplus of $2.5M (10.1% of revenue); 89% of revenue is its own.
B19: =debt_sentence -> Fernie uses 15% of its legal servicing limit. The $4.8M a year still available would service about $62.9M of new borrowing at 4.3% over 20 years.
B20: =asset_sentence -> Capital additions cover 96% of the renewal need: $348K a year short of keeping pace with wear.
B21: =plan_sentence -> Closing 100% of the renewal gap by year 5, borrowing 30% of the new capital, needs municipal tax increases averaging 3.7% a year. The representative house's municipal tax goes from $2,842 to $3,406, and debt servicing reaches 14% of the legal limit.
B22: {="A representative "&TEXT(YV(tbl_Year[house_value],LatestYear),"$#,##0")&" house pays "&TEXT(YV(tbl_Year[house_total_charges],LatestYear),"$#,##0")&" in property taxes and charges, against a tier median of "&TEXT(_xlfn.XLOOKUP(SelId,tbl_Peers[municipality_id],tbl_Peers[house_total_charges_tier_median]),"$#,##0")&"; "&TEXT(YV(tbl_Year[house_municipal_share],LatestYear),"0%")&" of it is the municipal share."} -> A representative $907,932 house pays $6,264 in property taxes and charges, against a tier median of $4,507; 45% of it is the municipal share.
B42: Independent analysis of the Province of British Columbia's Local Government Statistics (Open Government Licence – British Columbia). Not affiliated with or endorsed by any municipality or the Province. Built in Excel by Kush Patel.

Sheet Profile
B1: ="Six-year profile: "&Selected -> Six-year profile: Fernie
B2: Every line is the Province's schedule for that year, looked up for the selected municipality. A dash means the Province published nothing for that year.
B5: Line | C5: Column | D5: 2019 | E5: 2020 | F5: 2021 | G5: 2022 | H5: 2023 | I5: 2024 | J5: Change, first to last
B6: Revenue
B7: Taxation and grants in lieu | C7: taxation | D7: {=YV(_xlfn.XLOOKUP($C7,tbl_Year[#Headers],tbl_Year[]),D$5)} -> 11679941 | E7: {=YV(_xlfn.XLOOKUP($C7,tbl_Year[#Headers],tbl_Year[]),E$5)} -> 11847977 | F7: {=YV(_xlfn.XLOOKUP($C7,tbl_Year[#Headers],tbl_Year[]),F$5)} -> 12126305 | G7: {=YV(_xlfn.XLOOKUP($C7,tbl_Year[#Headers],tbl_Year[]),G$5)} -> 13369957 | H7: {=YV(_xlfn.XLOOKUP($C7,tbl_Year[#Headers],tbl_Year[]),H$5)} -> 14194174 | I7: {=YV(_xlfn.XLOOKUP($C7,tbl_Year[#Headers],tbl_Year[]),I$5)} -> 15074622 | J7: =IFERROR(I7/D7-1,"") -> 0.29064196
B8: Sale of services | C8: sale_of_services | D8: {=YV(_xlfn.XLOOKUP($C8,tbl_Year[#Headers],tbl_Year[]),D$5)} -> 4630558 | E8: {=YV(_xlfn.XLOOKUP($C8,tbl_Year[#Headers],tbl_Year[]),E$5)} -> 4796932 | F8: {=YV(_xlfn.XLOOKUP($C8,tbl_Year[#Headers],tbl_Year[]),F$5)} -> 5212081 | G8: {=YV(_xlfn.XLOOKUP($C8,tbl_Year[#Headers],tbl_Year[]),G$5)} -> 4985343 | H8: {=YV(_xlfn.XLOOKUP($C8,tbl_Year[#Headers],tbl_Year[]),H$5)} -> 5465696 | I8: {=YV(_xlfn.XLOOKUP($C8,tbl_Year[#Headers],tbl_Year[]),I$5)} -> 5910458 | J8: =IFERROR(I8/D8-1,"") -> 0.27640297
B9: Government transfers | C9: government_transfers | D9: {=YV(_xlfn.XLOOKUP($C9,tbl_Year[#Headers],tbl_Year[]),D$5)} -> 3063142 | E9: {=YV(_xlfn.XLOOKUP($C9,tbl_Year[#Headers],tbl_Year[]),E$5)} -> 3861857 | F9: {=YV(_xlfn.XLOOKUP($C9,tbl_Year[#Headers],tbl_Year[]),F$5)} -> 2132053 | G9: {=YV(_xlfn.XLOOKUP($C9,tbl_Year[#Headers],tbl_Year[]),G$5)} -> 9031310 | H9: {=YV(_xlfn.XLOOKUP($C9,tbl_Year[#Headers],tbl_Year[]),H$5)} -> 6032744 | I9: {=YV(_xlfn.XLOOKUP($C9,tbl_Year[#Headers],tbl_Year[]),I$5)} -> 2633114 | J9: =IFERROR(I9/D9-1,"") -> -0.14038788
B10: Investment income | C10: investment_income | D10: {=YV(_xlfn.XLOOKUP($C10,tbl_Year[#Headers],tbl_Year[]),D$5)} -> 297439 | E10: {=YV(_xlfn.XLOOKUP($C10,tbl_Year[#Headers],tbl_Year[]),E$5)} -> 99811 | F10: {=YV(_xlfn.XLOOKUP($C10,tbl_Year[#Headers],tbl_Year[]),F$5)} -> 116551 | G10: {=YV(_xlfn.XLOOKUP($C10,tbl_Year[#Headers],tbl_Year[]),G$5)} -> 448469 | H10: {=YV(_xlfn.XLOOKUP($C10,tbl_Year[#Headers],tbl_Year[]),H$5)} -> 839539 | I10: {=YV(_xlfn.XLOOKUP($C10,tbl_Year[#Headers],tbl_Year[]),I$5)} -> 897000 | J10: =IFERROR(I10/D10-1,"") -> 2.0157444
B11: Developer contributions | C11: developer_contributions | D11: {=YV(_xlfn.XLOOKUP($C11,tbl_Year[#Headers],tbl_Year[]),D$5)} -> 206600 | E11: {=YV(_xlfn.XLOOKUP($C11,tbl_Year[#Headers],tbl_Year[]),E$5)} -> -144741 | F11: {=YV(_xlfn.XLOOKUP($C11,tbl_Year[#Headers],tbl_Year[]),F$5)} -> 80000 | G11: {=YV(_xlfn.XLOOKUP($C11,tbl_Year[#Headers],tbl_Year[]),G$5)} -> 0 | H11: {=YV(_xlfn.XLOOKUP($C11,tbl_Year[#Headers],tbl_Year[]),H$5)} -> 0 | I11: {=YV(_xlfn.XLOOKUP($C11,tbl_Year[#Headers],tbl_Year[]),I$5)} -> 0 | J11: =IFERROR(I11/D11-1,"") -> -1
B12: Total revenue | C12: total_revenue | D12: {=YV(_xlfn.XLOOKUP($C12,tbl_Year[#Headers],tbl_Year[]),D$5)} -> 19992680 | E12: {=YV(_xlfn.XLOOKUP($C12,tbl_Year[#Headers],tbl_Year[]),E$5)} -> 20461836 | F12: {=YV(_xlfn.XLOOKUP($C12,tbl_Year[#Headers],tbl_Year[]),F$5)} -> 19666990 | G12: {=YV(_xlfn.XLOOKUP($C12,tbl_Year[#Headers],tbl_Year[]),G$5)} -> 27835079 | H12: {=YV(_xlfn.XLOOKUP($C12,tbl_Year[#Headers],tbl_Year[]),H$5)} -> 26532153 | I12: {=YV(_xlfn.XLOOKUP($C12,tbl_Year[#Headers],tbl_Year[]),I$5)} -> 24515194 | J12: =IFERROR(I12/D12-1,"") -> 0.22620849
B13: Expenses
B14: Cash expenses | C14: cash_expenses | D14: {=YV(_xlfn.XLOOKUP($C14,tbl_Year[#Headers],tbl_Year[]),D$5)} -> 13684373 | E14: {=YV(_xlfn.XLOOKUP($C14,tbl_Year[#Headers],tbl_Year[]),E$5)} -> 12791061 | F14: {=YV(_xlfn.XLOOKUP($C14,tbl_Year[#Headers],tbl_Year[]),F$5)} -> 13650961 | G14: {=YV(_xlfn.XLOOKUP($C14,tbl_Year[#Headers],tbl_Year[]),G$5)} -> 16539897 | H14: {=YV(_xlfn.XLOOKUP($C14,tbl_Year[#Headers],tbl_Year[]),H$5)} -> 17129644 | I14: {=YV(_xlfn.XLOOKUP($C14,tbl_Year[#Headers],tbl_Year[]),I$5)} -> 17764865 | J14: =IFERROR(I14/D14-1,"") -> 0.29818626
B15: Amortization | C15: amortization | D15: {=YV(_xlfn.XLOOKUP($C15,tbl_Year[#Headers],tbl_Year[]),D$5)} -> 3256048 | E15: {=YV(_xlfn.XLOOKUP($C15,tbl_Year[#Headers],tbl_Year[]),E$5)} -> 3471292 | F15: {=YV(_xlfn.XLOOKUP($C15,tbl_Year[#Headers],tbl_Year[]),F$5)} -> 3476738 | G15: {=YV(_xlfn.XLOOKUP($C15,tbl_Year[#Headers],tbl_Year[]),G$5)} -> 3644440 | H15: {=YV(_xlfn.XLOOKUP($C15,tbl_Year[#Headers],tbl_Year[]),H$5)} -> 4162923 | I15: {=YV(_xlfn.XLOOKUP($C15,tbl_Year[#Headers],tbl_Year[]),I$5)} -> 4268555 | J15: =IFERROR(I15/D15-1,"") -> 0.31096194
B16: Total expenses | C16: total_expenses | D16: {=YV(_xlfn.XLOOKUP($C16,tbl_Year[#Headers],tbl_Year[]),D$5)} -> 16940421 | E16: {=YV(_xlfn.XLOOKUP($C16,tbl_Year[#Headers],tbl_Year[]),E$5)} -> 16262353 | F16: {=YV(_xlfn.XLOOKUP($C16,tbl_Year[#Headers],tbl_Year[]),F$5)} -> 17127699 | G16: {=YV(_xlfn.XLOOKUP($C16,tbl_Year[#Headers],tbl_Year[]),G$5)} -> 20184337 | H16: {=YV(_xlfn.XLOOKUP($C16,tbl_Year[#Headers],tbl_Year[]),H$5)} -> 21292567 | I16: {=YV(_xlfn.XLOOKUP($C16,tbl_Year[#Headers],tbl_Year[]),I$5)} -> 22033420 | J16: =IFERROR(I16/D16-1,"") -> 0.30064182
B17: Annual surplus | C17: annual_surplus | D17: {=YV(_xlfn.XLOOKUP($C17,tbl_Year[#Headers],tbl_Year[]),D$5)} -> 3052259 | E17: {=YV(_xlfn.XLOOKUP($C17,tbl_Year[#Headers],tbl_Year[]),E$5)} -> 4199483 | F17: {=YV(_xlfn.XLOOKUP($C17,tbl_Year[#Headers],tbl_Year[]),F$5)} -> 2539291 | G17: {=YV(_xlfn.XLOOKUP($C17,tbl_Year[#Headers],tbl_Year[]),G$5)} -> 7650742 | H17: {=YV(_xlfn.XLOOKUP($C17,tbl_Year[#Headers],tbl_Year[]),H$5)} -> 5239586 | I17: {=YV(_xlfn.XLOOKUP($C17,tbl_Year[#Headers],tbl_Year[]),I$5)} -> 2481774 | J17: =IFERROR(I17/D17-1,"") -> -0.18690583
B18: Financial position
B19: Financial assets | C19: total_financial_assets | D19: {=YV(_xlfn.XLOOKUP($C19,tbl_Year[#Headers],tbl_Year[]),D$5)} -> 10154160 | E19: {=YV(_xlfn.XLOOKUP($C19,tbl_Year[#Headers],tbl_Year[]),E$5)} -> 16113500 | F19: {=YV(_xlfn.XLOOKUP($C19,tbl_Year[#Headers],tbl_Year[]),F$5)} -> 20138489 | G19: {=YV(_xlfn.XLOOKUP($C19,tbl_Year[#Headers],tbl_Year[]),G$5)} -> 21079484 | H19: {=YV(_xlfn.XLOOKUP($C19,tbl_Year[#Headers],tbl_Year[]),H$5)} -> 28409540 | I19: {=YV(_xlfn.XLOOKUP($C19,tbl_Year[#Headers],tbl_Year[]),I$5)} -> 24816939 | J19: =IFERROR(I19/D19-1,"") -> 1.4440169
B20: Liabilities | C20: total_liabilities | D20: {=YV(_xlfn.XLOOKUP($C20,tbl_Year[#Headers],tbl_Year[]),D$5)} -> 11339782 | E20: {=YV(_xlfn.XLOOKUP($C20,tbl_Year[#Headers],tbl_Year[]),E$5)} -> 13813880 | F20: {=YV(_xlfn.XLOOKUP($C20,tbl_Year[#Headers],tbl_Year[]),F$5)} -> 14367534 | G20: {=YV(_xlfn.XLOOKUP($C20,tbl_Year[#Headers],tbl_Year[]),G$5)} -> 15411959 | H20: {=YV(_xlfn.XLOOKUP($C20,tbl_Year[#Headers],tbl_Year[]),H$5)} -> 21941329 | I20: {=YV(_xlfn.XLOOKUP($C20,tbl_Year[#Headers],tbl_Year[]),I$5)} -> 16880536 | J20: =IFERROR(I20/D20-1,"") -> 0.48861204
B21: Net financial assets | C21: net_financial_assets | D21: {=YV(_xlfn.XLOOKUP($C21,tbl_Year[#Headers],tbl_Year[]),D$5)} -> -1185622 | E21: {=YV(_xlfn.XLOOKUP($C21,tbl_Year[#Headers],tbl_Year[]),E$5)} -> 2299620 | F21: {=YV(_xlfn.XLOOKUP($C21,tbl_Year[#Headers],tbl_Year[]),F$5)} -> 5770955 | G21: {=YV(_xlfn.XLOOKUP($C21,tbl_Year[#Headers],tbl_Year[]),G$5)} -> 5667525 | H21: {=YV(_xlfn.XLOOKUP($C21,tbl_Year[#Headers],tbl_Year[]),H$5)} -> 6468211 | I21: {=YV(_xlfn.XLOOKUP($C21,tbl_Year[#Headers],tbl_Year[]),I$5)} -> 7936403 | J21: =IFERROR(I21/D21-1,"") -> -7.6938729
B22: Reserves and operating/capital surplus | C22: financial_reserves | D22: {=YV(_xlfn.XLOOKUP($C22,tbl_Year[#Headers],tbl_Year[]),D$5)} -> 1525280 | E22: {=YV(_xlfn.XLOOKUP($C22,tbl_Year[#Headers],tbl_Year[]),E$5)} -> 7852727 | F22: {=YV(_xlfn.XLOOKUP($C22,tbl_Year[#Headers],tbl_Year[]),F$5)} -> 11185508 | G22: {=YV(_xlfn.XLOOKUP($C22,tbl_Year[#Headers],tbl_Year[]),G$5)} -> 9738321 | H22: {=YV(_xlfn.XLOOKUP($C22,tbl_Year[#Headers],tbl_Year[]),H$5)} -> 10859555 | I22: {=YV(_xlfn.XLOOKUP($C22,tbl_Year[#Headers],tbl_Year[]),I$5)} -> 13420201 | J22: =IFERROR(I22/D22-1,"") -> 7.7985163
B23: Long-term debt | C23: long_term_debt | D23: {=YV(_xlfn.XLOOKUP($C23,tbl_Year[#Headers],tbl_Year[]),D$5)} -> 2686653 | E23: {=YV(_xlfn.XLOOKUP($C23,tbl_Year[#Headers],tbl_Year[]),E$5)} -> 5553107 | F23: {=YV(_xlfn.XLOOKUP($C23,tbl_Year[#Headers],tbl_Year[]),F$5)} -> 4814554 | G23: {=YV(_xlfn.XLOOKUP($C23,tbl_Year[#Headers],tbl_Year[]),G$5)} -> 4070796 | H23: {=YV(_xlfn.XLOOKUP($C23,tbl_Year[#Headers],tbl_Year[]),H$5)} -> 3321143 | I23: {=YV(_xlfn.XLOOKUP($C23,tbl_Year[#Headers],tbl_Year[]),I$5)} -> 2566095 | J23: =IFERROR(I23/D23-1,"") -> -0.044872933
B24: Debt capacity
B25: Revenue for the liability limit | C25: revenue_for_limit | D25: {=YV(_xlfn.XLOOKUP($C25,tbl_Year[#Headers],tbl_Year[]),D$5)} -> 16741329 | E25: {=YV(_xlfn.XLOOKUP($C25,tbl_Year[#Headers],tbl_Year[]),E$5)} -> 16801219 | F25: {=YV(_xlfn.XLOOKUP($C25,tbl_Year[#Headers],tbl_Year[]),F$5)} -> 17578972 | G25: {=YV(_xlfn.XLOOKUP($C25,tbl_Year[#Headers],tbl_Year[]),G$5)} -> 18739359 | H25: {=YV(_xlfn.XLOOKUP($C25,tbl_Year[#Headers],tbl_Year[]),H$5)} -> 20973687 | I25: {=YV(_xlfn.XLOOKUP($C25,tbl_Year[#Headers],tbl_Year[]),I$5)} -> 22410266 | J25: =IFERROR(I25/D25-1,"") -> 0.33861929
B26: Liability servicing limit (25%) | C26: liability_servicing_limit | D26: {=YV(_xlfn.XLOOKUP($C26,tbl_Year[#Headers],tbl_Year[]),D$5)} -> 4185332 | E26: {=YV(_xlfn.XLOOKUP($C26,tbl_Year[#Headers],tbl_Year[]),E$5)} -> 4200305 | F26: {=YV(_xlfn.XLOOKUP($C26,tbl_Year[#Headers],tbl_Year[]),F$5)} -> 4394743 | G26: {=YV(_xlfn.XLOOKUP($C26,tbl_Year[#Headers],tbl_Year[]),G$5)} -> 4684840 | H26: {=YV(_xlfn.XLOOKUP($C26,tbl_Year[#Headers],tbl_Year[]),H$5)} -> 5243422 | I26: {=YV(_xlfn.XLOOKUP($C26,tbl_Year[#Headers],tbl_Year[]),I$5)} -> 5602567 | J26: =IFERROR(I26/D26-1,"") -> 0.33861949
B27: Actual debt servicing | C27: debt_servicing_cost | D27: {=YV(_xlfn.XLOOKUP($C27,tbl_Year[#Headers],tbl_Year[]),D$5)} -> 243269 | E27: {=YV(_xlfn.XLOOKUP($C27,tbl_Year[#Headers],tbl_Year[]),E$5)} -> 200042 | F27: {=YV(_xlfn.XLOOKUP($C27,tbl_Year[#Headers],tbl_Year[]),F$5)} -> 824208 | G27: {=YV(_xlfn.XLOOKUP($C27,tbl_Year[#Headers],tbl_Year[]),G$5)} -> 851682 | H27: {=YV(_xlfn.XLOOKUP($C27,tbl_Year[#Headers],tbl_Year[]),H$5)} -> 885711 | I27: {=YV(_xlfn.XLOOKUP($C27,tbl_Year[#Headers],tbl_Year[]),I$5)} -> 851154 | J27: =IFERROR(I27/D27-1,"") -> 2.4988182
B28: Share of the limit used | C28: limit_used | D28: {=YV(_xlfn.XLOOKUP($C28,tbl_Year[#Headers],tbl_Year[]),D$5)} -> 0.058124182 | E28: {=YV(_xlfn.XLOOKUP($C28,tbl_Year[#Headers],tbl_Year[]),E$5)} -> 0.047625589 | F28: {=YV(_xlfn.XLOOKUP($C28,tbl_Year[#Headers],tbl_Year[]),F$5)} -> 0.18754407 | G28: {=YV(_xlfn.XLOOKUP($C28,tbl_Year[#Headers],tbl_Year[]),G$5)} -> 0.18179532 | H28: {=YV(_xlfn.XLOOKUP($C28,tbl_Year[#Headers],tbl_Year[]),H$5)} -> 0.1689185 | I28: {=YV(_xlfn.XLOOKUP($C28,tbl_Year[#Headers],tbl_Year[]),I$5)} -> 0.15192215 | J28: =IFERROR(I28-D28,"") -> 0.093797963
B29: Assets and tax
B30: Capital additions | C30: tca_additions | D30: {=YV(_xlfn.XLOOKUP($C30,tbl_Year[#Headers],tbl_Year[]),D$5)} -> 13873447 | E30: {=YV(_xlfn.XLOOKUP($C30,tbl_Year[#Headers],tbl_Year[]),E$5)} -> 4209779 | F30: {=YV(_xlfn.XLOOKUP($C30,tbl_Year[#Headers],tbl_Year[]),F$5)} -> 2544694 | G30: {=YV(_xlfn.XLOOKUP($C30,tbl_Year[#Headers],tbl_Year[]),G$5)} -> 10814019 | H30: {=YV(_xlfn.XLOOKUP($C30,tbl_Year[#Headers],tbl_Year[]),H$5)} -> 7572883 | I30: {=YV(_xlfn.XLOOKUP($C30,tbl_Year[#Headers],tbl_Year[]),I$5)} -> 5282136 | J30: =IFERROR(I30/D30-1,"") -> -0.6192629
B31: Replacement value | C31: replacement_value | D31: {=YV(_xlfn.XLOOKUP($C31,tbl_Year[#Headers],tbl_Year[]),D$5)} -> 287234599 | E31: {=YV(_xlfn.XLOOKUP($C31,tbl_Year[#Headers],tbl_Year[]),E$5)} -> 296225505 | F31: {=YV(_xlfn.XLOOKUP($C31,tbl_Year[#Headers],tbl_Year[]),F$5)} -> 299497019 | G31: {=YV(_xlfn.XLOOKUP($C31,tbl_Year[#Headers],tbl_Year[]),G$5)} -> 313485667 | H31: {=YV(_xlfn.XLOOKUP($C31,tbl_Year[#Headers],tbl_Year[]),H$5)} -> 322621947 | I31: {=YV(_xlfn.XLOOKUP($C31,tbl_Year[#Headers],tbl_Year[]),I$5)} -> 365516873 | J31: =IFERROR(I31/D31-1,"") -> 0.27253776
B32: Municipal property tax | C32: municipal_property_tax | D32: {=YV(_xlfn.XLOOKUP($C32,tbl_Year[#Headers],tbl_Year[]),D$5)} -> 10743925 | E32: {=YV(_xlfn.XLOOKUP($C32,tbl_Year[#Headers],tbl_Year[]),E$5)} -> 10997472 | F32: {=YV(_xlfn.XLOOKUP($C32,tbl_Year[#Headers],tbl_Year[]),F$5)} -> 11502422 | G32: {=YV(_xlfn.XLOOKUP($C32,tbl_Year[#Headers],tbl_Year[]),G$5)} -> 12425297 | H32: {=YV(_xlfn.XLOOKUP($C32,tbl_Year[#Headers],tbl_Year[]),H$5)} -> 13139811 | I32: {=YV(_xlfn.XLOOKUP($C32,tbl_Year[#Headers],tbl_Year[]),I$5)} -> 13957961 | J32: =IFERROR(I32/D32-1,"") -> 0.29914912
B33: Representative house value | C33: house_value | D33: {=YV(_xlfn.XLOOKUP($C33,tbl_Year[#Headers],tbl_Year[]),D$5)} -> 527027 | E33: {=YV(_xlfn.XLOOKUP($C33,tbl_Year[#Headers],tbl_Year[]),E$5)} -> 569308 | F33: {=YV(_xlfn.XLOOKUP($C33,tbl_Year[#Headers],tbl_Year[]),F$5)} -> 619538 | G33: {=YV(_xlfn.XLOOKUP($C33,tbl_Year[#Headers],tbl_Year[]),G$5)} -> 736170 | H33: {=YV(_xlfn.XLOOKUP($C33,tbl_Year[#Headers],tbl_Year[]),H$5)} -> 876753 | I33: {=YV(_xlfn.XLOOKUP($C33,tbl_Year[#Headers],tbl_Year[]),I$5)} -> 907932 | J33: =IFERROR(I33/D33-1,"") -> 0.72274286
B34: Taxes and charges, representative house | C34: house_total_charges | D34: {=YV(_xlfn.XLOOKUP($C34,tbl_Year[#Headers],tbl_Year[]),D$5)} -> 4761.0779 | E34: {=YV(_xlfn.XLOOKUP($C34,tbl_Year[#Headers],tbl_Year[]),E$5)} -> 4954 | F34: {=YV(_xlfn.XLOOKUP($C34,tbl_Year[#Headers],tbl_Year[]),F$5)} -> 5203 | G34: {=YV(_xlfn.XLOOKUP($C34,tbl_Year[#Headers],tbl_Year[]),G$5)} -> 5491 | H34: {=YV(_xlfn.XLOOKUP($C34,tbl_Year[#Headers],tbl_Year[]),H$5)} -> 5937 | I34: {=YV(_xlfn.XLOOKUP($C34,tbl_Year[#Headers],tbl_Year[]),I$5)} -> 6264 | J34: =IFERROR(I34/D34-1,"") -> 0.31566845
B35: Population (BC Stats estimate) | C35: population | D35: {=YV(_xlfn.XLOOKUP($C35,tbl_Year[#Headers],tbl_Year[]),D$5)} -> 5744 | E35: {=YV(_xlfn.XLOOKUP($C35,tbl_Year[#Headers],tbl_Year[]),E$5)} -> 5668 | F35: {=YV(_xlfn.XLOOKUP($C35,tbl_Year[#Headers],tbl_Year[]),F$5)} -> 5739 | G35: {=YV(_xlfn.XLOOKUP($C35,tbl_Year[#Headers],tbl_Year[]),G$5)} -> 5869.5 | H35: {=YV(_xlfn.XLOOKUP($C35,tbl_Year[#Headers],tbl_Year[]),H$5)} -> 6000 | I35: {=YV(_xlfn.XLOOKUP($C35,tbl_Year[#Headers],tbl_Year[]),I$5)} -> 6000 | J35: =IFERROR(I35/D35-1,"") -> 0.044568245

Sheet Peers
B1: ="Peers: "&Selected&" against "&SelTierLabel -> Peers: Fernie against 2,500 to 9,999 residents
B2: Every active municipality in the same population tier, from the latest year. Percentiles count only municipalities that report the metric; 100% is the highest value, which is the best only where the direction says so.
B4: The selected municipality on every metric
B5: Metric | C5: Key | D5: Value | E5: Tier median | F5: Tier percentile | G5: Province percentile | H5: Direction | I5: Reading
B6: Revenue per resident | C6: revenue_per_capita | D6: {=_xlfn.XLOOKUP(SelId,tbl_Peers[municipality_id],_xlfn.XLOOKUP("revenue_per_capita",tbl_Peers[#Headers],tbl_Peers[]),"")} -> 4085.8657 | E6: {=_xlfn.XLOOKUP(SelId,tbl_Peers[municipality_id],_xlfn.XLOOKUP("revenue_per_capita_tier_median",tbl_Peers[#Headers],tbl_Peers[]),"")} -> 3327.878 | F6: {=_xlfn.LET(_xlpm.c,_xlfn.XLOOKUP("revenue_per_capita",tbl_Peers[#Headers],tbl_Peers[]),_xlpm.v,D6,_xlpm.t,tbl_Peers[size_tier]=SelTier,IF(_xlpm.v="","",SUM(_xlpm.t*(_xlpm.c<>"")*(_xlpm.c<_xlpm.v))/(SUM(_xlpm.t*(_xlpm.c<>""))-1)))} -> 0.66666667 | G6: {=_xlfn.LET(_xlpm.c,_xlfn.XLOOKUP("revenue_per_capita",tbl_Peers[#Headers],tbl_Peers[]),_xlpm.v,D6,IF(_xlpm.v="","",SUM((_xlpm.c<>"")*(_xlpm.c<_xlpm.v))/(SUM(--(_xlpm.c<>""))-1)))} -> 0.62580645 | H6: context | I6: =IF(D6="","not reported",IF(H6="context",IF(D6>E6,"above","below")&" the tier median",IF((D6>E6)=(H6="higher"),"better","weaker")&" than the tier median")) -> above the tier median
B7: Spending per resident | C7: expenses_per_capita | D7: {=_xlfn.XLOOKUP(SelId,tbl_Peers[municipality_id],_xlfn.XLOOKUP("expenses_per_capita",tbl_Peers[#Headers],tbl_Peers[]),"")} -> 3672.2367 | E7: {=_xlfn.XLOOKUP(SelId,tbl_Peers[municipality_id],_xlfn.XLOOKUP("expenses_per_capita_tier_median",tbl_Peers[#Headers],tbl_Peers[]),"")} -> 2783.6651 | F7: {=_xlfn.LET(_xlpm.c,_xlfn.XLOOKUP("expenses_per_capita",tbl_Peers[#Headers],tbl_Peers[]),_xlpm.v,D7,_xlpm.t,tbl_Peers[size_tier]=SelTier,IF(_xlpm.v="","",SUM(_xlpm.t*(_xlpm.c<>"")*(_xlpm.c<_xlpm.v))/(SUM(_xlpm.t*(_xlpm.c<>""))-1)))} -> 0.88888889 | G7: {=_xlfn.LET(_xlpm.c,_xlfn.XLOOKUP("expenses_per_capita",tbl_Peers[#Headers],tbl_Peers[]),_xlpm.v,D7,IF(_xlpm.v="","",SUM((_xlpm.c<>"")*(_xlpm.c<_xlpm.v))/(SUM(--(_xlpm.c<>""))-1)))} -> 0.77419355 | H7: context | I7: =IF(D7="","not reported",IF(H7="context",IF(D7>E7,"above","below")&" the tier median",IF((D7>E7)=(H7="higher"),"better","weaker")&" than the tier median")) -> above the tier median
B8: Municipal property tax per resident | C8: municipal_tax_per_capita | D8: {=_xlfn.XLOOKUP(SelId,tbl_Peers[municipality_id],_xlfn.XLOOKUP("municipal_tax_per_capita",tbl_Peers[#Headers],tbl_Peers[]),"")} -> 2326.3268 | E8: {=_xlfn.XLOOKUP(SelId,tbl_Peers[municipality_id],_xlfn.XLOOKUP("municipal_tax_per_capita_tier_median",tbl_Peers[#Headers],tbl_Peers[]),"")} -> 1246.362 | F8: {=_xlfn.LET(_xlpm.c,_xlfn.XLOOKUP("municipal_tax_per_capita",tbl_Peers[#Headers],tbl_Peers[]),_xlpm.v,D8,_xlpm.t,tbl_Peers[size_tier]=SelTier,IF(_xlpm.v="","",SUM(_xlpm.t*(_xlpm.c<>"")*(_xlpm.c<_xlpm.v))/(SUM(_xlpm.t*(_xlpm.c<>""))-1)))} -> 0.95555556 | G8: {=_xlfn.LET(_xlpm.c,_xlfn.XLOOKUP("municipal_tax_per_capita",tbl_Peers[#Headers],tbl_Peers[]),_xlpm.v,D8,IF(_xlpm.v="","",SUM((_xlpm.c<>"")*(_xlpm.c<_xlpm.v))/(SUM(--(_xlpm.c<>""))-1)))} -> 0.92405063 | H8: context | I8: =IF(D8="","not reported",IF(H8="context",IF(D8>E8,"above","below")&" the tier median",IF((D8>E8)=(H8="higher"),"better","weaker")&" than the tier median")) -> above the tier median
B9: Own-source share of revenue | C9: own_source_share | D9: {=_xlfn.XLOOKUP(SelId,tbl_Peers[municipality_id],_xlfn.XLOOKUP("own_source_share",tbl_Peers[#Headers],tbl_Peers[]),"")} -> 0.89259257 | E9: {=_xlfn.XLOOKUP(SelId,tbl_Peers[municipality_id],_xlfn.XLOOKUP("own_source_share_tier_median",tbl_Peers[#Headers],tbl_Peers[]),"")} -> 0.77321957 | F9: {=_xlfn.LET(_xlpm.c,_xlfn.XLOOKUP("own_source_share",tbl_Peers[#Headers],tbl_Peers[]),_xlpm.v,D9,_xlpm.t,tbl_Peers[size_tier]=SelTier,IF(_xlpm.v="","",SUM(_xlpm.t*(_xlpm.c<>"")*(_xlpm.c<_xlpm.v))/(SUM(_xlpm.t*(_xlpm.c<>""))-1)))} -> 0.97777778 | G9: {=_xlfn.LET(_xlpm.c,_xlfn.XLOOKUP("own_source_share",tbl_Peers[#Headers],tbl_Peers[]),_xlpm.v,D9,IF(_xlpm.v="","",SUM((_xlpm.c<>"")*(_xlpm.c<_xlpm.v))/(SUM(--(_xlpm.c<>""))-1)))} -> 0.85806452 | H9: higher | I9: =IF(D9="","not reported",IF(H9="context",IF(D9>E9,"above","below")&" the tier median",IF((D9>E9)=(H9="higher"),"better","weaker")&" than the tier median")) -> better than the tier median
B10: Annual surplus as a share of revenue | C10: surplus_ratio | D10: {=_xlfn.XLOOKUP(SelId,tbl_Peers[municipality_id],_xlfn.XLOOKUP("surplus_ratio",tbl_Peers[#Headers],tbl_Peers[]),"")} -> 0.10123412 | E10: {=_xlfn.XLOOKUP(SelId,tbl_Peers[municipality_id],_xlfn.XLOOKUP("surplus_ratio_tier_median",tbl_Peers[#Headers],tbl_Peers[]),"")} -> 0.21663632 | F10: {=_xlfn.LET(_xlpm.c,_xlfn.XLOOKUP("surplus_ratio",tbl_Peers[#Headers],tbl_Peers[]),_xlpm.v,D10,_xlpm.t,tbl_Peers[size_tier]=SelTier,IF(_xlpm.v="","",SUM(_xlpm.t*(_xlpm.c<>"")*(_xlpm.c<_xlpm.v))/(SUM(_xlpm.t*(_xlpm.c<>""))-1)))} -> 0.17777778 | G10: {=_xlfn.LET(_xlpm.c,_xlfn.XLOOKUP("surplus_ratio",tbl_Peers[#Headers],tbl_Peers[]),_xlpm.v,D10,IF(_xlpm.v="","",SUM((_xlpm.c<>"")*(_xlpm.c<_xlpm.v))/(SUM(--(_xlpm.c<>""))-1)))} -> 0.17419355 | H10: higher | I10: =IF(D10="","not reported",IF(H10="context",IF(D10>E10,"above","below")&" the tier median",IF((D10>E10)=(H10="higher"),"better","weaker")&" than the tier median")) -> weaker than the tier median
B11: Share of the legal debt-servicing limit used | C11: limit_used | D11: {=_xlfn.XLOOKUP(SelId,tbl_Peers[municipality_id],_xlfn.XLOOKUP("limit_used",tbl_Peers[#Headers],tbl_Peers[]),"")} -> 0.15192215 | E11: {=_xlfn.XLOOKUP(SelId,tbl_Peers[municipality_id],_xlfn.XLOOKUP("limit_used_tier_median",tbl_Peers[#Headers],tbl_Peers[]),"")} -> 0.15427955 | F11: {=_xlfn.LET(_xlpm.c,_xlfn.XLOOKUP("limit_used",tbl_Peers[#Headers],tbl_Peers[]),_xlpm.v,D11,_xlpm.t,tbl_Peers[size_tier]=SelTier,IF(_xlpm.v="","",SUM(_xlpm.t*(_xlpm.c<>"")*(_xlpm.c<_xlpm.v))/(SUM(_xlpm.t*(_xlpm.c<>""))-1)))} -> 0.48888889 | G11: {=_xlfn.LET(_xlpm.c,_xlfn.XLOOKUP("limit_used",tbl_Peers[#Headers],tbl_Peers[]),_xlpm.v,D11,IF(_xlpm.v="","",SUM((_xlpm.c<>"")*(_xlpm.c<_xlpm.v))/(SUM(--(_xlpm.c<>""))-1)))} -> 0.62580645 | H11: lower | I11: =IF(D11="","not reported",IF(H11="context",IF(D11>E11,"above","below")&" the tier median",IF((D11>E11)=(H11="higher"),"better","weaker")&" than the tier median")) -> better than the tier median
B12: Long-term debt per resident | C12: debt_per_capita | D12: {=_xlfn.XLOOKUP(SelId,tbl_Peers[municipality_id],_xlfn.XLOOKUP("debt_per_capita",tbl_Peers[#Headers],tbl_Peers[]),"")} -> 427.6825 | E12: {=_xlfn.XLOOKUP(SelId,tbl_Peers[municipality_id],_xlfn.XLOOKUP("debt_per_capita_tier_median",tbl_Peers[#Headers],tbl_Peers[]),"")} -> 950.36657 | F12: {=_xlfn.LET(_xlpm.c,_xlfn.XLOOKUP("debt_per_capita",tbl_Peers[#Headers],tbl_Peers[]),_xlpm.v,D12,_xlpm.t,tbl_Peers[size_tier]=SelTier,IF(_xlpm.v="","",SUM(_xlpm.t*(_xlpm.c<>"")*(_xlpm.c<_xlpm.v))/(SUM(_xlpm.t*(_xlpm.c<>""))-1)))} -> 0.26666667 | G12: {=_xlfn.LET(_xlpm.c,_xlfn.XLOOKUP("debt_per_capita",tbl_Peers[#Headers],tbl_Peers[]),_xlpm.v,D12,IF(_xlpm.v="","",SUM((_xlpm.c<>"")*(_xlpm.c<_xlpm.v))/(SUM(--(_xlpm.c<>""))-1)))} -> 0.43870968 | H12: lower | I12: =IF(D12="","not reported",IF(H12="context",IF(D12>E12,"above","below")&" the tier median",IF((D12>E12)=(H12="higher"),"better","weaker")&" than the tier median")) -> better than the tier median
B13: Reserves and surplus per resident | C13: reserves_per_capita | D13: {=_xlfn.XLOOKUP(SelId,tbl_Peers[municipality_id],_xlfn.XLOOKUP("reserves_per_capita",tbl_Peers[#Headers],tbl_Peers[]),"")} -> 2236.7002 | E13: {=_xlfn.XLOOKUP(SelId,tbl_Peers[municipality_id],_xlfn.XLOOKUP("reserves_per_capita_tier_median",tbl_Peers[#Headers],tbl_Peers[]),"")} -> 4022.5271 | F13: {=_xlfn.LET(_xlpm.c,_xlfn.XLOOKUP("reserves_per_capita",tbl_Peers[#Headers],tbl_Peers[]),_xlpm.v,D13,_xlpm.t,tbl_Peers[size_tier]=SelTier,IF(_xlpm.v="","",SUM(_xlpm.t*(_xlpm.c<>"")*(_xlpm.c<_xlpm.v))/(SUM(_xlpm.t*(_xlpm.c<>""))-1)))} -> 0.088888889 | G13: {=_xlfn.LET(_xlpm.c,_xlfn.XLOOKUP("reserves_per_capita",tbl_Peers[#Headers],tbl_Peers[]),_xlpm.v,D13,IF(_xlpm.v="","",SUM((_xlpm.c<>"")*(_xlpm.c<_xlpm.v))/(SUM(--(_xlpm.c<>""))-1)))} -> 0.18064516 | H13: higher | I13: =IF(D13="","not reported",IF(H13="context",IF(D13>E13,"above","below")&" the tier median",IF((D13>E13)=(H13="higher"),"better","weaker")&" than the tier median")) -> weaker than the tier median
B14: Reserves against a year of cash spending | C14: reserves_to_cash_expenses | D14: {=_xlfn.XLOOKUP(SelId,tbl_Peers[municipality_id],_xlfn.XLOOKUP("reserves_to_cash_expenses",tbl_Peers[#Headers],tbl_Peers[]),"")} -> 0.75543501 | E14: {=_xlfn.XLOOKUP(SelId,tbl_Peers[municipality_id],_xlfn.XLOOKUP("reserves_to_cash_expenses_tier_median",tbl_Peers[#Headers],tbl_Peers[]),"")} -> 1.8328982 | F14: {=_xlfn.LET(_xlpm.c,_xlfn.XLOOKUP("reserves_to_cash_expenses",tbl_Peers[#Headers],tbl_Peers[]),_xlpm.v,D14,_xlpm.t,tbl_Peers[size_tier]=SelTier,IF(_xlpm.v="","",SUM(_xlpm.t*(_xlpm.c<>"")*(_xlpm.c<_xlpm.v))/(SUM(_xlpm.t*(_xlpm.c<>""))-1)))} -> 0.022222222 | G14: {=_xlfn.LET(_xlpm.c,_xlfn.XLOOKUP("reserves_to_cash_expenses",tbl_Peers[#Headers],tbl_Peers[]),_xlpm.v,D14,IF(_xlpm.v="","",SUM((_xlpm.c<>"")*(_xlpm.c<_xlpm.v))/(SUM(--(_xlpm.c<>""))-1)))} -> 0.058064516 | H14: higher | I14: =IF(D14="","not reported",IF(H14="context",IF(D14>E14,"above","below")&" the tier median",IF((D14>E14)=(H14="higher"),"better","weaker")&" than the tier median")) -> weaker than the tier median
B15: Share of asset life used up | C15: asset_consumption_ratio | D15: {=_xlfn.XLOOKUP(SelId,tbl_Peers[municipality_id],_xlfn.XLOOKUP("asset_consumption_ratio",tbl_Peers[#Headers],tbl_Peers[]),"")} -> 0.41173021 | E15: {=_xlfn.XLOOKUP(SelId,tbl_Peers[municipality_id],_xlfn.XLOOKUP("asset_consumption_ratio_tier_median",tbl_Peers[#Headers],tbl_Peers[]),"")} -> 0.42596276 | F15: {=_xlfn.LET(_xlpm.c,_xlfn.XLOOKUP("asset_consumption_ratio",tbl_Peers[#Headers],tbl_Peers[]),_xlpm.v,D15,_xlpm.t,tbl_Peers[size_tier]=SelTier,IF(_xlpm.v="","",SUM(_xlpm.t*(_xlpm.c<>"")*(_xlpm.c<_xlpm.v))/(SUM(_xlpm.t*(_xlpm.c<>""))-1)))} -> 0.4 | G15: {=_xlfn.LET(_xlpm.c,_xlfn.XLOOKUP("asset_consumption_ratio",tbl_Peers[#Headers],tbl_Peers[]),_xlpm.v,D15,IF(_xlpm.v="","",SUM((_xlpm.c<>"")*(_xlpm.c<_xlpm.v))/(SUM(--(_xlpm.c<>""))-1)))} -> 0.38064516 | H15: lower | I15: =IF(D15="","not reported",IF(H15="context",IF(D15>E15,"above","below")&" the tier median",IF((D15>E15)=(H15="higher"),"better","weaker")&" than the tier median")) -> better than the tier median
B16: Capital reinvestment against renewal need | C16: reinvestment_ratio | D16: {=_xlfn.XLOOKUP(SelId,tbl_Peers[municipality_id],_xlfn.XLOOKUP("reinvestment_ratio",tbl_Peers[#Headers],tbl_Peers[]),"")} -> 0.95779831 | E16: {=_xlfn.XLOOKUP(SelId,tbl_Peers[municipality_id],_xlfn.XLOOKUP("reinvestment_ratio_tier_median",tbl_Peers[#Headers],tbl_Peers[]),"")} -> 1.0599919 | F16: {=_xlfn.LET(_xlpm.c,_xlfn.XLOOKUP("reinvestment_ratio",tbl_Peers[#Headers],tbl_Peers[]),_xlpm.v,D16,_xlpm.t,tbl_Peers[size_tier]=SelTier,IF(_xlpm.v="","",SUM(_xlpm.t*(_xlpm.c<>"")*(_xlpm.c<_xlpm.v))/(SUM(_xlpm.t*(_xlpm.c<>""))-1)))} -> 0.43589744 | G16: {=_xlfn.LET(_xlpm.c,_xlfn.XLOOKUP("reinvestment_ratio",tbl_Peers[#Headers],tbl_Peers[]),_xlpm.v,D16,IF(_xlpm.v="","",SUM((_xlpm.c<>"")*(_xlpm.c<_xlpm.v))/(SUM(--(_xlpm.c<>""))-1)))} -> 0.49230769 | H16: higher | I16: =IF(D16="","not reported",IF(H16="context",IF(D16>E16,"above","below")&" the tier median",IF((D16>E16)=(H16="higher"),"better","weaker")&" than the tier median")) -> weaker than the tier median
B17: Taxes and charges on a representative house | C17: house_total_charges | D17: {=_xlfn.XLOOKUP(SelId,tbl_Peers[municipality_id],_xlfn.XLOOKUP("house_total_charges",tbl_Peers[#Headers],tbl_Peers[]),"")} -> 6264 | E17: {=_xlfn.XLOOKUP(SelId,tbl_Peers[municipality_id],_xlfn.XLOOKUP("house_total_charges_tier_median",tbl_Peers[#Headers],tbl_Peers[]),"")} -> 4506.5 | F17: {=_xlfn.LET(_xlpm.c,_xlfn.XLOOKUP("house_total_charges",tbl_Peers[#Headers],tbl_Peers[]),_xlpm.v,D17,_xlpm.t,tbl_Peers[size_tier]=SelTier,IF(_xlpm.v="","",SUM(_xlpm.t*(_xlpm.c<>"")*(_xlpm.c<_xlpm.v))/(SUM(_xlpm.t*(_xlpm.c<>""))-1)))} -> 0.86666667 | G17: {=_xlfn.LET(_xlpm.c,_xlfn.XLOOKUP("house_total_charges",tbl_Peers[#Headers],tbl_Peers[]),_xlpm.v,D17,IF(_xlpm.v="","",SUM((_xlpm.c<>"")*(_xlpm.c<_xlpm.v))/(SUM(--(_xlpm.c<>""))-1)))} -> 0.79746835 | H17: lower | I17: =IF(D17="","not reported",IF(H17="context",IF(D17>E17,"above","below")&" the tier median",IF((D17>E17)=(H17="higher"),"better","weaker")&" than the tier median")) -> weaker than the tier median
B18: Municipal tax per $1,000 of assessment | C18: effective_municipal_rate | D18: {=_xlfn.XLOOKUP(SelId,tbl_Peers[municipality_id],_xlfn.XLOOKUP("effective_municipal_rate",tbl_Peers[#Headers],tbl_Peers[]),"")} -> 4.8324159 | E18: {=_xlfn.XLOOKUP(SelId,tbl_Peers[municipality_id],_xlfn.XLOOKUP("effective_municipal_rate_tier_median",tbl_Peers[#Headers],tbl_Peers[]),"")} -> 4.3304406 | F18: {=_xlfn.LET(_xlpm.c,_xlfn.XLOOKUP("effective_municipal_rate",tbl_Peers[#Headers],tbl_Peers[]),_xlpm.v,D18,_xlpm.t,tbl_Peers[size_tier]=SelTier,IF(_xlpm.v="","",SUM(_xlpm.t*(_xlpm.c<>"")*(_xlpm.c<_xlpm.v))/(SUM(_xlpm.t*(_xlpm.c<>""))-1)))} -> 0.62222222 | G18: {=_xlfn.LET(_xlpm.c,_xlfn.XLOOKUP("effective_municipal_rate",tbl_Peers[#Headers],tbl_Peers[]),_xlpm.v,D18,IF(_xlpm.v="","",SUM((_xlpm.c<>"")*(_xlpm.c<_xlpm.v))/(SUM(--(_xlpm.c<>""))-1)))} -> 0.63291139 | H18: lower | I18: =IF(D18="","not reported",IF(H18="context",IF(D18>E18,"above","below")&" the tier median",IF((D18>E18)=(H18="higher"),"better","weaker")&" than the tier median")) -> weaker than the tier median
B21: The tier, ranked
B22: Rank the tier by | D22: Share of the legal debt-servicing limit used | G22: =_xlfn.XLOOKUP(D22,B6:B18,C6:C18) -> limit_used
B23: Municipality | C23: Population | D23: Value | E23: Regional district
B24: {=_xlfn.LET(_xlpm.c,_xlfn.XLOOKUP(G22,tbl_Peers[#Headers],tbl_Peers[]),_xlpm.keep,(tbl_Peers[size_tier]=SelTier)*(_xlpm.c<>""),_xlfn.SORTBY(_xlfn._xlws.FILTER(_xlfn.HSTACK(tbl_Peers[display_name],tbl_Peers[population],_xlpm.c,tbl_Peers[regional_district]&""),_xlpm.keep),_xlfn._xlws.FILTER(_xlpm.c,_xlpm.keep),-1))} -> Golden | C24: 4455 | D24: 0.87420592 | E24: COL
B25: Peachland | C25: 6382 | D25: 0.33175721 | E25: COK
B26: Gibsons | C26: 5098 | D26: 0.29353887 | E26: SUN
B27: Invermere | C27: 3910 | D27: 0.28976738 | E27: EKO
B28: Trail | C28: 8480 | D28: 0.28348561 | E28: KOO
B29: Oliver | C29: 5824 | D29: 0.27823678 | E29: OKS
B30: Revelstoke | C30: 8617 | D30: 0.26897539 | E30: COL
B31: Cumberland | C31: 4901 | D31: 0.26443686 | E31: COM
B32: Bowen Island | C32: 4181 | D32: 0.26111081 | E32: MVRD
B33: Merritt | C33: 7809 | D33: 0.25012126 | E33: TNR
B34: Ladysmith | C34: 9690 | D34: 0.24631014 | E34: COW
B35: Princeton | C35: 3333 | D35: 0.23400777 | E35: OKS
B36: Elkford | C36: 2805 | D36: 0.23079681 | E36: EKO
... B38: Rossland | C38: 4390 | D38: 0.22244766 | E38: KOO
B39: Northern Rockies | C39: 4400 | D39: 0.192659
B40: Pemberton | C40: 3678 | D40: 0.18407837 | E40: SQL
B41: Tofino | C41: 2653 | D41: 0.18188387 | E41: ALB
B42: Sicamous | C42: 3005 | D42: 0.17717121 | E42: COL
B43: Osoyoos | C43: 5730 | D43: 0.16173193 | E43: OKS
B44: Vanderhoof | C44: 4839 | D44: 0.16071929 | E44: BUL
...

Sheet Assets
B1: ="Infrastructure: "&Selected&", "&LatestYear -> Infrastructure: Fernie, 2024
B2: Schedule 503: what the municipality owns, what it would cost to replace, and whether capital spending keeps up with wear. The renewal need is re-derived, because the Province's own field is not usable as published (see Province).
B4: Assets by category, latest year
B5: Category | C5: Historical cost | D5: Accumulated amortization | E5: Net book value | F5: Additions | G5: Replacement value | H5: Life used up | I5: Asset management plan | J5: Replacement value share
B6: {=_xlfn.LET(_xlpm.k,(tbl_Assets[municipality_id]=SelId)*(tbl_Assets[year]=LatestYear),_xlpm.d,_xlfn._xlws.FILTER(_xlfn.HSTACK(tbl_Assets[asset_category],tbl_Assets[historical_cost],tbl_Assets[accumulated_amortization],tbl_Assets[net_book_value],tbl_Assets[additions],tbl_Assets[replacement_value],tbl_Assets[consumption_ratio],SUBSTITUTE(tbl_Assets[amp_status]&"","_"," ")),_xlpm.k,""),_xlfn.SORTBY(_xlpm.d,_xlfn.CHOOSECOLS(_xlpm.d,6),-1))} -> Buildings | C6: 27847711 | D6: 11018999 | E6: 16828712 | F6: 478157 | G6: 94976440 | H6: 0.39568778 | I6: In Progress | J6: {=IFERROR(_xlfn.CHOOSECOLS(_xlfn.ANCHORARRAY(B6),6)/SUM(_xlfn.CHOOSECOLS(_xlfn.ANCHORARRAY(B6),6)),"")} -> 0.25984147
B7: Transportation System | C7: 46235209 | D7: 23998201 | E7: 22237008 | F7: 1692305 | G7: 88140126 | H7: 0.51904602 | I7: In Progress | J7: 0.24113832
B8: Water System | C8: 38989296 | D8: 11183684 | E8: 27805612 | F8: 383797 | G8: 58886174 | H8: 0.28683985 | I8: In Progress | J8: 0.16110385
B9: Sewer System | C9: 28934056 | D9: 12195448 | E9: 16738608 | F9: 103877 | G9: 41426092 | H9: 0.42149113 | I9: In Progress | J9: 0.11333565
B10: Drainage System | C10: 12295932 | D10: 6120208 | E10: 6175724 | F10: 92948 | G10: 30242160 | H10: 0.49774251 | I10: In Progress | J10: 0.082738068
B11: Parks and Recreation | C11: 15035272 | D11: 1922661 | E11: 13112611 | F11: 2548597 | G11: 25456198 | H11: 0.1278767 | I11: In Progress | J11: 0.069644385
B12: Fleet | C12: 14478454 | D12: 9243371 | E12: 5235083 | F12: 1181386 | G12: 15594339 | H12: 0.63842251 | I12: In Progress | J12: 0.042663801
B13: Work In Progress | C13: 6381384 | D13: 0 | E13: 6381384 | F13: -1198931 | G13: 6381384 | H13: 0 | I13: Not applicable | J13: 0.017458521
B14: Land | C14: 4413960 | D14: 0 | E14: 4413960 | F14: 0 | G14: 4413960 | H14: 0 | I14: Not applicable | J14: 0.01207594
B15: Other Engineering Systems | C15: 0 | D15: 0 | E15: 0 | F15: 0 | G15: 0 | H15: 0 | J15: 0
B16: Other Tangible Capital Assets | C16: 0 | D16: 0 | E16: 0 | F16: 0 | G16: 0 | H16: 0 | I16: Not applicable | J16: 0
B20: Renewal: is capital spending keeping up with wear?
B21: Data quality of the replacement values | E21: {=YV(tbl_Year[asset_data_quality],LatestYear)} -> plausible
B22: Replacement value against historical cost | E22: {=YV(tbl_Year[replacement_to_cost],LatestYear)} -> 1.9297649
B23: Amortization this year | E23: {=YV(tbl_Year[amortization],LatestYear)} -> 4268555
B24: Renewal need (amortization at replacement cost) | E24: {=YV(tbl_Year[renewal_need],LatestYear)} -> 8237307.6
B25: Capital additions, three-year average | E25: {=YV(tbl_Year[tca_additions_3yr],LatestYear)} -> 7889679.3
B26: Reinvestment ratio | E26: {=YV(tbl_Year[reinvestment_ratio],LatestYear)} -> 0.95779831
B27: Annual renewal gap | E27: {=YV(tbl_Year[annual_renewal_gap],LatestYear)} -> 347628.26
B28: Share of replacement value under an asset management plan | E28: {=YV(tbl_Year[amp_coverage],LatestYear)} -> 0
B29: Share of asset life used up (depreciable assets) | E29: {=YV(tbl_Year[asset_consumption_ratio],LatestYear)} -> 0.41173021
B31: {=IF(E21<>"plausible","The replacement values do not pass the screen ("&E21&"), so no renewal need is estimated for "&Selected&".",IF(E26<1,"Capital additions cover "&TEXT(E26,"0%")&" of the renewal need: "&MONEY(E27)&" a year short of keeping pace with wear.","Capital additions exceed the renewal need ("&TEXT(E26,"0.00")&"x). They include growth assets, so this is an upper bound on renewal."))} -> Capital additions cover 96% of the renewal need: $348K a year short of keeping pace with wear.

Sheet Plan
B1: ="Five-year financial plan: "&Selected -> Five-year financial plan: Fernie
B2: The plan the Community Charter (s.165) requires, built from the latest statements: costs grow with wages, prices and population; the renewal gap closes on a straight line to the target; new capital is funded from debt, reserves and taxation in the shares below. The output is the tax increase each year needs.
B4: Drivers (change the yellow cells)
B5: Inflation (CPI) | E5: 0.025 | G5: Base year (latest with statements) | J5: =BaseYear -> 2024
B6: Wage and contract growth | E6: 0.035 | G6: Population growth, two-year average | J6: {=IFERROR((YV(tbl_Year[population],BaseYear)/YV(tbl_Year[population],BaseYear-2))^(1/2)-1,0)} -> 0.011055676
B7: Wage-like share of cash costs | E7: 0.55 | G7: Cost growth (wages, prices, population) | J7: =plan_wage_share*plan_wage+(1-plan_wage_share)*plan_cpi+plan_pop_growth -> 0.041555676
B8: Share of the renewal gap closed by year 5 | E8: 1 | G8: Growth in revenue other than taxation | J8: =plan_cpi+plan_pop_growth -> 0.036055676
B9: Share of new capital borrowed | E9: 0.3 | G9: Base capital program (three-year average additions) | J9: {=_xlfn.LET(_xlpm.a,YV(tbl_Year[tca_additions_3yr],BaseYear),IF(_xlpm.a="",N(YV(tbl_Year[tca_additions],BaseYear)),_xlpm.a))} -> 7889679.3
B10: Share of new capital from reserves | E10: 0.2 | G10: Annual renewal gap at the base year | J10: {=N(YV(tbl_Year[annual_renewal_gap],BaseYear))} -> 347628.26
B11: MFA borrowing rate | E11: 0.043
B12: Borrowing term (years) | E12: 20
B14: The plan
D15: Year 0 | E15: Year 1 | F15: Year 2 | G15: Year 3 | H15: Year 4 | I15: Year 5
B16: Year | D16: =BaseYear+COLUMN()-COLUMN($D$16) -> 2024 | E16: =BaseYear+COLUMN()-COLUMN($D$16) -> 2025 | F16: =BaseYear+COLUMN()-COLUMN($D$16) -> 2026 | G16: =BaseYear+COLUMN()-COLUMN($D$16) -> 2027 | H16: =BaseYear+COLUMN()-COLUMN($D$16) -> 2028 | I16: =BaseYear+COLUMN()-COLUMN($D$16) -> 2029
B17: Cash operating expenses | D17: {=YV(tbl_Year[cash_expenses],BaseYear)*(1+plan_cost_growth)^(COLUMN()-COLUMN($D$1))} -> 17764865 | E17: {=YV(tbl_Year[cash_expenses],BaseYear)*(1+plan_cost_growth)^(COLUMN()-COLUMN($D$1))} -> 18503096 | F17: {=YV(tbl_Year[cash_expenses],BaseYear)*(1+plan_cost_growth)^(COLUMN()-COLUMN($D$1))} -> 19272005 | G17: {=YV(tbl_Year[cash_expenses],BaseYear)*(1+plan_cost_growth)^(COLUMN()-COLUMN($D$1))} -> 20072866 | H17: {=YV(tbl_Year[cash_expenses],BaseYear)*(1+plan_cost_growth)^(COLUMN()-COLUMN($D$1))} -> 20907007 | I17: {=YV(tbl_Year[cash_expenses],BaseYear)*(1+plan_cost_growth)^(COLUMN()-COLUMN($D$1))} -> 21775812
B18: Revenue other than taxation | D18: {=(YV(tbl_Year[total_revenue],BaseYear)-YV(tbl_Year[taxation],BaseYear))*(1+plan_rev_growth)^(COLUMN()-COLUMN($D$1))} -> 9440572 | E18: {=(YV(tbl_Year[total_revenue],BaseYear)-YV(tbl_Year[taxation],BaseYear))*(1+plan_rev_growth)^(COLUMN()-COLUMN($D$1))} -> 9780958.2 | F18: {=(YV(tbl_Year[total_revenue],BaseYear)-YV(tbl_Year[taxation],BaseYear))*(1+plan_rev_growth)^(COLUMN()-COLUMN($D$1))} -> 10133617 | G18: {=(YV(tbl_Year[total_revenue],BaseYear)-YV(tbl_Year[taxation],BaseYear))*(1+plan_rev_growth)^(COLUMN()-COLUMN($D$1))} -> 10498992 | H18: {=(YV(tbl_Year[total_revenue],BaseYear)-YV(tbl_Year[taxation],BaseYear))*(1+plan_rev_growth)^(COLUMN()-COLUMN($D$1))} -> 10877540 | I18: {=(YV(tbl_Year[total_revenue],BaseYear)-YV(tbl_Year[taxation],BaseYear))*(1+plan_rev_growth)^(COLUMN()-COLUMN($D$1))} -> 11269737
B19: Capital program | D19: =(plan_base_capital+plan_gap*plan_closure*(COLUMN()-COLUMN($D$1))/5)*(1+plan_cpi)^(COLUMN()-COLUMN($D$1)) -> 7889679.3 | E19: =(plan_base_capital+plan_gap*plan_closure*(COLUMN()-COLUMN($D$1))/5)*(1+plan_cpi)^(COLUMN()-COLUMN($D$1)) -> 8158185.1 | F19: =(plan_base_capital+plan_gap*plan_closure*(COLUMN()-COLUMN($D$1))/5)*(1+plan_cpi)^(COLUMN()-COLUMN($D$1)) -> 8435185.1 | G19: =(plan_base_capital+plan_gap*plan_closure*(COLUMN()-COLUMN($D$1))/5)*(1+plan_cpi)^(COLUMN()-COLUMN($D$1)) -> 8720936.3 | H19: =(plan_base_capital+plan_gap*plan_closure*(COLUMN()-COLUMN($D$1))/5)*(1+plan_cpi)^(COLUMN()-COLUMN($D$1)) -> 9015703 | I19: =(plan_base_capital+plan_gap*plan_closure*(COLUMN()-COLUMN($D$1))/5)*(1+plan_cpi)^(COLUMN()-COLUMN($D$1)) -> 9319757.5
B20: Capital above the base-year program | D20: =D19-plan_base_capital -> 0 | E20: =E19-plan_base_capital -> 268505.78 | F20: =F19-plan_base_capital -> 545505.79 | G20: =G19-plan_base_capital -> 831256.94 | H20: =H19-plan_base_capital -> 1126023.7 | I20: =I19-plan_base_capital -> 1430078.1
B21: New borrowing | D21: =plan_debt*D20 -> 0 | E21: =plan_debt*E20 -> 80551.733 | F21: =plan_debt*F20 -> 163651.74 | G21: =plan_debt*G20 -> 249377.08 | H21: =plan_debt*H20 -> 337807.1 | I21: =plan_debt*I20 -> 429023.44
B22: Servicing on new borrowing | D22: {=SUM(PMT(plan_rate,plan_term,-$D21:D21))} -> 0 | E22: {=SUM(PMT(plan_rate,plan_term,-$D21:E21))} -> 6085.6549 | F22: {=SUM(PMT(plan_rate,plan_term,-$D21:F21))} -> 18449.486 | G22: {=SUM(PMT(plan_rate,plan_term,-$D21:G21))} -> 37289.836 | H22: {=SUM(PMT(plan_rate,plan_term,-$D21:H21))} -> 62811.042 | I22: {=SUM(PMT(plan_rate,plan_term,-$D21:I21))} -> 95223.611
B23: Drawn from reserves | D23: =plan_reserve*D20 -> 0 | E23: =plan_reserve*E20 -> 53701.155 | F23: =plan_reserve*F20 -> 109101.16 | G23: =plan_reserve*G20 -> 166251.39 | H23: =plan_reserve*H20 -> 225204.73 | I23: =plan_reserve*I20 -> 286015.63
B24: Capital funded from taxation | D24: =(1-plan_debt-plan_reserve)*D20 -> 0 | E24: =(1-plan_debt-plan_reserve)*E20 -> 134252.89 | F24: =(1-plan_debt-plan_reserve)*F20 -> 272752.9 | G24: =(1-plan_debt-plan_reserve)*G20 -> 415628.47 | H24: =(1-plan_debt-plan_reserve)*H20 -> 563011.83 | I24: =(1-plan_debt-plan_reserve)*I20 -> 715039.07
B25: Taxation required | D25: {=YV(tbl_Year[taxation],BaseYear)+(D17-$D17)+D22+D24-(D18-$D18)} -> 15074622 | E25: {=YV(tbl_Year[taxation],BaseYear)+(E17-$D17)+E22+E24-(E18-$D18)} -> 15612805 | F25: {=YV(tbl_Year[taxation],BaseYear)+(F17-$D17)+F22+F24-(F18-$D18)} -> 16179919 | G25: {=YV(tbl_Year[taxation],BaseYear)+(G17-$D17)+G22+G24-(G18-$D18)} -> 16777121 | H25: {=YV(tbl_Year[taxation],BaseYear)+(H17-$D17)+H22+H24-(H18-$D18)} -> 17405619 | I25: {=YV(tbl_Year[taxation],BaseYear)+(I17-$D17)+I22+I24-(I18-$D18)} -> 18066667
B26: Increase on the year before | E26: =E25/D25-1 -> 0.035701281 | F26: =F25/E25-1 -> 0.036323609 | G26: =G25/F25-1 -> 0.036910117 | H26: =H25/G25-1 -> 0.037461601 | I26: =I25/H25-1 -> 0.037978975
B27: Reserves and surplus, closing | D27: {=YV(tbl_Year[financial_reserves],BaseYear)-SUM($D23:D23)} -> 13420201 | E27: {=YV(tbl_Year[financial_reserves],BaseYear)-SUM($D23:E23)} -> 13366500 | F27: {=YV(tbl_Year[financial_reserves],BaseYear)-SUM($D23:F23)} -> 13257399 | G27: {=YV(tbl_Year[financial_reserves],BaseYear)-SUM($D23:G23)} -> 13091147 | H27: {=YV(tbl_Year[financial_reserves],BaseYear)-SUM($D23:H23)} -> 12865943 | I27: {=YV(tbl_Year[financial_reserves],BaseYear)-SUM($D23:I23)} -> 12579927
B28: Total debt servicing | D28: {=YV(tbl_Year[debt_servicing_cost],BaseYear)+D22} -> 851154 | E28: {=YV(tbl_Year[debt_servicing_cost],BaseYear)+E22} -> 857239.65 | F28: {=YV(tbl_Year[debt_servicing_cost],BaseYear)+F22} -> 869603.49 | G28: {=YV(tbl_Year[debt_servicing_cost],BaseYear)+G22} -> 888443.84 | H28: {=YV(tbl_Year[debt_servicing_cost],BaseYear)+H22} -> 913965.04 | I28: {=YV(tbl_Year[debt_servicing_cost],BaseYear)+I22} -> 946377.61
B29: Share of the legal limit used | D29: {=D28/(0.25*YV(tbl_Year[revenue_for_limit],BaseYear)*(D25+D18)/($D25+$D18))} -> 0.15192216 | E29: {=E28/(0.25*YV(tbl_Year[revenue_for_limit],BaseYear)*(E25+E18)/($D25+$D18))} -> 0.14771462 | F29: {=F28/(0.25*YV(tbl_Year[revenue_for_limit],BaseYear)*(F25+F18)/($D25+$D18))} -> 0.14460735 | G29: {=G28/(0.25*YV(tbl_Year[revenue_for_limit],BaseYear)*(G25+G18)/($D25+$D18))} -> 0.14252656 | H29: {=H28/(0.25*YV(tbl_Year[revenue_for_limit],BaseYear)*(H25+H18)/($D25+$D18))} -> 0.14140019 | I29: {=I28/(0.25*YV(tbl_Year[revenue_for_limit],BaseYear)*(I25+I18)/($D25+$D18))} -> 0.14115813
B30: Municipal tax on the representative house | D30: {=YV(tbl_Year[house_municipal_tax],BaseYear)*D25/$D25} -> 2842 | E30: {=YV(tbl_Year[house_municipal_tax],BaseYear)*E25/$D25} -> 2943.463 | F30: {=YV(tbl_Year[house_municipal_tax],BaseYear)*F25/$D25} -> 3050.3802 | G30: {=YV(tbl_Year[house_municipal_tax],BaseYear)*G25/$D25} -> 3162.9701 | H30: {=YV(tbl_Year[house_municipal_tax],BaseYear)*H25/$D25} -> 3281.4601 | I30: {=YV(tbl_Year[house_municipal_tax],BaseYear)*I25/$D25} -> 3406.0865
B32: Average tax increase a year, years 1 to 5 | E32: =(I25/D25)^(1/5)-1 -> 0.036874803
B33: ="Closing "&TEXT(plan_closure,"0%")&" of the renewal gap by year 5, borrowing "&TEXT(plan_debt,"0%")&" of the new capital, needs municipal tax increases averaging "&TEXT(E32,"0.0%")&" a year. The representative house's municipal tax goes from "&TEXT(D30,"$#,##0")&" to "&TEXT(I30,"$#,##0")&", and debt servicing reaches "&TEXT(I29,"0%")&" of the legal limit." -> Closing 100% of the renewal gap by year 5, borrowing 30% of the new capital, needs municipal tax increases averaging 3.7% a year. The representative house's municipal tax goes from $2,842 to $3,406, and debt servicing reaches 14% of the legal limit.
B35: What-if data table: average tax increase by gap closure and debt share
B36: Gap closed ↓ Debt share → | C36: =E32 -> 0.036874803 | D36: 0 | E36: 0.15 | F36: 0.3 | G36: 0.45 | H36: 0.6
C37: 0 | D37: 0.037094546 | E37: 0.03570487 | F37: 0.034307695 | G37: 0.03290293 | H37: 0.031490481
C38: 0.25 | D38: 0.037995122 | E38: 0.03647796 | F38: 0.034951863 | G38: 0.033416711 | H38: 0.031872383
C39: 0.5 | D39: 0.038892583 | E39: 0.037248751 | F39: 0.035594431 | G39: 0.033929473 | H39: 0.03225372
C40: 0.75 | D40: 0.039786954 | E40: 0.038017257 | F40: 0.036235408 | G40: 0.034441219 | H40: 0.032634495
C41: 1 | D41: 0.040678258 | E41: 0.038783494 | F41: 0.036874803 | G41: 0.034951955 | H41: 0.033014709

Sheet Tax
B1: ="Property tax by class: "&Selected&", "&LatestYear -> Property tax by class: Fernie, 2024
B2: Schedule 707. BC sets each class's rate as a multiple of the residential rate, so one number, the residential rate, sets them all. The calculator turns a levy change into the rates that raise it.
B4: The classes
B5: Property class | C5: Assessment | D5: Rate per $1,000 | E5: Class multiple | F5: Variable-rate taxes | G5: Flat and other taxes | H5: Municipal taxes | I5: Share of taxes | J5: Assessment × multiple
B6: {=_xlfn.LET(_xlpm.k,(tbl_Tax[municipality_id]=SelId)*(tbl_Tax[year]=LatestYear),_xlpm.d,_xlfn._xlws.FILTER(_xlfn.HSTACK(tbl_Tax[property_class],tbl_Tax[assessment],tbl_Tax[municipal_rate],tbl_Tax[class_multiple],tbl_Tax[variable_rate_taxes],tbl_Tax[flat_and_other_taxes],tbl_Tax[municipal_taxes]),_xlpm.k,""),_xlfn.SORTBY(_xlpm.d,_xlfn.CHOOSECOLS(_xlpm.d,7),-1))} -> Residential | C6: 2643674301 | D6: 3.13073 | E6: 1 | F6: 8276630 | G6: 0 | H6: 8276630 | I6: {=IFERROR(_xlfn.CHOOSECOLS(_xlfn.ANCHORARRAY(B6),7)/SUM(_xlfn.CHOOSECOLS(_xlfn.ANCHORARRAY(B6),7)),"")} -> 0.58805896 | J6: {=IFERROR(_xlfn.CHOOSECOLS(_xlfn.ANCHORARRAY(B6),2)*_xlfn.CHOOSECOLS(_xlfn.ANCHORARRAY(B6),4),"")} -> 2643674301
B7: Major Industry | C7: 0 | D7: 0 | E7: 0 | F7: 0 | G7: 3461569 | H7: 3461569 | I7: 0.24594632 | J7: 0
B8: Business/Other | C8: 238390989 | D8: 8.75733 | E8: 2.7972166 | F8: 2087669 | G8: 0 | H8: 2087669 | I8: 0.14832999 | J8: 6.6683124e+08
B9: Utilities | C9: 3182720 | D9: 33.83754 | E9: 10.808195 | F9: 107695 | G9: 116529 | H9: 224224 | I9: 0.015931234 | J9: 34399458
B10: Light Industry | C10: 1932800 | D10: 10.64449 | E10: 3.4000026 | F10: 20574 | G10: 0 | H10: 20574 | I10: 0.0014617936 | J10: 6571524.9
B11: Recreation | C11: 1207000 | D11: 3.13073 | E11: 1 | F11: 3779 | G11: 0 | H11: 3779 | I11: 0.00026849996 | J11: 1207000
B12: Farm | C12: 14438 | D12: 3.13073 | E12: 1 | F12: 45 | G12: 0 | H12: 45 | I12: 3.1972739e-06 | J12: 14438
B13: Managed Forest | C13: 0 | D13: 0 | E13: 0 | F13: 0 | G13: 0 | H13: 0 | I13: 0 | J13: 0
B14: Supportive Housing | C14: 2 | D14: 3.13073 | E14: 1 | F14: 0 | G14: 0 | H14: 0 | I14: 0 | J14: 2
B18: Levy to rates
B19: Variable-rate levy this year | F19: =SUM(_xlfn.CHOOSECOLS(_xlfn.ANCHORARRAY(B6),5)) -> 10496392
B20: Assessment weighted by class multiples | F20: =SUM(_xlfn.ANCHORARRAY(J6)) -> 3.352698e+09
B21: Residential rate the levy implies (per $1,000) | F21: =tax_variable_levy*1000/tax_weighted_base -> 3.13073
B22: Residential rate the Province publishes | F22: {=_xlfn.XLOOKUP("Residential",_xlfn.CHOOSECOLS(_xlfn.ANCHORARRAY(B6),1),_xlfn.CHOOSECOLS(_xlfn.ANCHORARRAY(B6),3),"")} -> 3.13073
B23: Levy change to test (defaults to plan year 1) | F23: =plan_year1_increase -> 0.035701281
B24: New residential rate | F24: =tax_res_rate_implied*(1+tax_levy_change) -> 3.242501
B25: Representative house value | F25: {=YV(tbl_Year[house_value],LatestYear)} -> 907932
B26: Municipal tax on it now | F26: {=YV(tbl_Year[house_municipal_tax],LatestYear)} -> 2842
B27: Municipal tax on it after the change | F27: =tax_house_now*(1+tax_levy_change) -> 2943.463
